Workbook

Sheet Painel
B1: 💰 CONTROLE FINANCEIRO TOTAL — MENTE MILIONÁRIA 2026
B4: 🏦 SALDO EM TEMPO REAL | E4: 💵 TOTAL ENTRADAS ANO | H4: 💸 TOTAL SAÍDAS ANO | K4: 📊 TAXA DE POUPANÇA
B5: ='Configuração'!D6+E5-H5 -> -9463.78 | E5: =O23 -> 6393 | H5: =O26 -> 15856.78 | K5: =IF(E5=0,0,(E5-H5)/E5) -> -1.4803347
B7: 💵 DE ONDE VEM O DINHEIRO — POR FONTE DE RECEITA
B8: Fonte de Receita | C8: Jan | D8: Fev | E8: Mar | F8: Abr | G8: Mai | H8: Jun | I8: Jul | J8: Ago | K8: Set | L8: Out | M8: Nov | N8: Dez | O8: TOTAL
B9: Salário CLT | C9: =Janeiro!M7 -> 0 | D9: =Fevereiro!M7 -> 0 | E9: ='Março'!M7 -> 0 | F9: =Abril!M7 -> 0 | G9: =Maio!M7 -> 0 | H9: =Junho!M7 -> 0 | I9: =Julho!M7 -> 0 | J9: =Agosto!M7 -> 0 | K9: =Setembro!M7 -> 0 | L9: =Outubro!M7 -> 0 | M9: =Novembro!M7 -> 0 | N9: =Dezembro!M7 -> 0 | O9: =SUM(C9:N9) -> 0 | P9: Salário CLT
B10: Freelance / Projetos | C10: =Janeiro!M8 -> 0 | D10: =Fevereiro!M8 -> 0 | E10: ='Março'!M8 -> 0 | F10: =Abril!M8 -> 0 | G10: =Maio!M8 -> 0 | H10: =Junho!M8 -> 0 | I10: =Julho!M8 -> 0 | J10: =Agosto!M8 -> 0 | K10: =Setembro!M8 -> 0 | L10: =Outubro!M8 -> 0 | M10: =Novembro!M8 -> 0 | N10: =Dezembro!M8 -> 0 | O10: =SUM(C10:N10) -> 0 | P10: Freelance / Projetos
B11: Vendas Online | C11: =Janeiro!M9 -> 0 | D11: =Fevereiro!M9 -> 0 | E11: ='Março'!M9 -> 0 | F11: =Abril!M9 -> 0 | G11: =Maio!M9 -> 0 | H11: =Junho!M9 -> 0 | I11: =Julho!M9 -> 0 | J11: =Agosto!M9 -> 0 | K11: =Setembro!M9 -> 0 | L11: =Outubro!M9 -> 0 | M11: =Novembro!M9 -> 0 | N11: =Dezembro!M9 -> 0 | O11: =SUM(C11:N11) -> 0 | P11: Vendas Online
B12: Consultoria | C12: =Janeiro!M10 -> 0 | D12: =Fevereiro!M10 -> 0 | E12: ='Março'!M10 -> 0 | F12: =Abril!M10 -> 0 | G12: =Maio!M10 -> 0 | H12: =Junho!M10 -> 0 | I12: =Julho!M10 -> 0 | J12: =Agosto!M10 -> 0 | K12: =Setembro!M10 -> 0 | L12: =Outubro!M10 -> 0 | M12: =Novembro!M10 -> 0 | N12: =Dezembro!M10 -> 0 | O12: =SUM(C12:N12) -> 0 | P12: Consultoria
B13: Rendimentos / Investimentos | C13: =Janeiro!M11 -> 0 | D13: =Fevereiro!M11 -> 0 | E13: ='Março'!M11 -> 0 | F13: =Abril!M11 -> 0 | G13: =Maio!M11 -> 0 | H13: =Junho!M11 -> 0 | I13: =Julho!M11 -> 0 | J13: =Agosto!M11 -> 0 | K13: =Setembro!M11 -> 0 | L13: =Outubro!M11 -> 0 | M13: =Novembro!M11 -> 0 | N13: =Dezembro!M11 -> 0 | O13: =SUM(C13:N13) -> 0 | P13: Rendimentos / Investimentos
B14: Aluguel Recebido | C14: =Janeiro!M12 -> 0 | D14: =Fevereiro!M12 -> 0 | E14: ='Março'!M12 -> 0 | F14: =Abril!M12 -> 0 | G14: =Maio!M12 -> 0 | H14: =Junho!M12 -> 0 | I14: =Julho!M12 -> 0 | J14: =Agosto!M12 -> 0 | K14: =Setembro!M12 -> 0 | L14: =Outubro!M12 -> 0 | M14: =Novembro!M12 -> 0 | N14: =Dezembro!M12 -> 0 | O14: =SUM(C14:N14) -> 0 | P14: Aluguel Recebido
B15: Comissões | C15: =Janeiro!M13 -> 0 | D15: =Fevereiro!M13 -> 0 | E15: ='Março'!M13 -> 0 | F15: =Abril!M13 -> 0 | G15: =Maio!M13 -> 0 | H15: =Junho!M13 -> 0 | I15: =Julho!M13 -> 0 | J15: =Agosto!M13 -> 0 | K15: =Setembro!M13 -> 0 | L15: =Outubro!M13 -> 0 | M15: =Novembro!M13 -> 0 | N15: =Dezembro!M13 -> 0 | O15: =SUM(C15:N15) -> 0 | P15: Comissões
B16: Bônus / Participação | C16: =Janeiro!M14 -> 0 | D16: =Fevereiro!M14 -> 0 | E16: ='Março'!M14 -> 0 | F16: =Abril!M14 -> 0 | G16: =Maio!M14 -> 0 | H16: =Junho!M14 -> 0 | I16: =Julho!M14 -> 0 | J16: =Agosto!M14 -> 0 | K16: =Setembro!M14 -> 0 | L16: =Outubro!M14 -> 0 | M16: =Novembro!M14 -> 0 | N16: =Dezembro!M14 -> 0 | O16: =SUM(C16:N16) -> 0 | P16: Bônus / Participação
B17: Renda Extra / Bico | C17: =Janeiro!M15 -> 0 | D17: =Fevereiro!M15 -> 0 | E17: ='Março'!M15 -> 0 | F17: =Abril!M15 -> 0 | G17: =Maio!M15 -> 0 | H17: =Junho!M15 -> 0 | I17: =Julho!M15 -> 0 | J17: =Agosto!M15 -> 0 | K17: =Setembro!M15 -> 0 | L17: =Outubro!M15 -> 0 | M17: =Novembro!M15 -> 0 | N17: =Dezembro!M15 -> 0 | O17: =SUM(C17:N17) -> 0 | P17: Renda Extra / Bico
B18: Outros | C18: =Janeiro!M16 -> 0 | D18: =Fevereiro!M16 -> 0 | E18: ='Março'!M16 -> 0 | F18: =Abril!M16 -> 0 | G18: =Maio!M16 -> 0 | H18: =Junho!M16 -> 0 | I18: =Julho!M16 -> 0 | J18: =Agosto!M16 -> 0 | K18: =Setembro!M16 -> 0 | L18: =Outubro!M16 -> 0 | M18: =Novembro!M16 -> 0 | N18: =Dezembro!M16 -> 0 | O18: =SUM(C18:N18) -> 0 | P18: Outros
B19: 📊 TOTAL | C19: =SUM(C9:C18) -> 0 | D19: =SUM(D9:D18) -> 0 | E19: =SUM(E9:E18) -> 0 | F19: =SUM(F9:F18) -> 0 | G19: =SUM(G9:G18) -> 0 | H19: =SUM(H9:H18) -> 0 | I19: =SUM(I9:I18) -> 0 | J19: =SUM(J9:J18) -> 0 | ... O19: =SUM(O9:O18) -> 0
B21: 📊 FLUXO DE CAIXA — ENTRADAS vs SAÍDAS vs SALDO MENSAL
C22: Jan | D22: Fev | E22: Mar | F22: Abr | G22: Mai | H22: Jun | I22: Jul | J22: Ago | K22: Set | L22: Out | M22: Nov | N22: Dez | O22: TOTAL
B23: 💵 Total Entradas | C23: =Janeiro!D5 -> 0 | D23: =Fevereiro!D5 -> 6393 | E23: ='Março'!D5 -> 0 | F23: =Abril!D5 -> 0 | G23: =Maio!D5 -> 0 | H23: =Junho!D5 -> 0 | I23: =Julho!D5 -> 0 | J23: =Agosto!D5 -> 0 | K23: =Setembro!D5 -> 0 | L23: =Outubro!D5 -> 0 | M23: =Novembro!D5 -> 0 | N23: =Dezembro!D5 -> 0 | O23: =SUM(C23:N23) -> 6393
B24: 🔒 Despesas Fixas | C24: =Janeiro!D6 -> 1184.9 | D24: =Fevereiro!D6 -> 1184.9 | E24: ='Março'!D6 -> 1184.9 | F24: =Abril!D6 -> 1184.9 | G24: =Maio!D6 -> 1184.9 | H24: =Junho!D6 -> 1184.9 | I24: =Julho!D6 -> 1184.9 | J24: =Agosto!D6 -> 1184.9 | K24: =Setembro!D6 -> 1184.9 | L24: =Outubro!D6 -> 1184.9 | M24: =Novembro!D6 -> 1184.9 | N24: =Dezembro!D6 -> 1184.9 | O24: =SUM(C24:N24) -> 14218.8
B25: 🛒 Despesas Variáveis | C25: =Janeiro!D7 -> 0 | D25: =Fevereiro!D7 -> 1637.98 | E25: ='Março'!D7 -> 0 | F25: =Abril!D7 -> 0 | G25: =Maio!D7 -> 0 | H25: =Junho!D7 -> 0 | I25: =Julho!D7 -> 0 | J25: =Agosto!D7 -> 0 | K25: =Setembro!D7 -> 0 | L25: =Outubro!D7 -> 0 | M25: =Novembro!D7 -> 0 | N25: =Dezembro!D7 -> 0 | O25: =SUM(C25:N25) -> 1637.98
B26: 💸 Total Saídas | C26: =C24+C25 -> 1184.9 | D26: =D24+D25 -> 2822.88 | E26: =E24+E25 -> 1184.9 | F26: =F24+F25 -> 1184.9 | G26: =G24+G25 -> 1184.9 | H26: =H24+H25 -> 1184.9 | I26: =I24+I25 -> 1184.9 | J26: =J24+J25 -> 1184.9 | ... N26: =N24+N25 -> 1184.9 | O26: =SUM(C26:N26) -> 15856.78
B27: 📈 Saldo do Mês | C27: =C23-C26 -> -1184.9 | D27: =D23-D26 -> 3570.12 | E27: =E23-E26 -> -1184.9 | F27: =F23-F26 -> -1184.9 | G27: =G23-G26 -> -1184.9 | H27: =H23-H26 -> -1184.9 | I27: =I23-I26 -> -1184.9 | J27: =J23-J26 -> -1184.9 | ... N27: =N23-N26 -> -1184.9 | O27: =SUM(C27:N27) -> -9463.78
B28: 💰 Saldo Acumulado | C28: ='Configuração'!D6+C27 -> -1184.9 | D28: =C28+D27 -> 2385.22 | E28: =D28+E27 -> 1200.32 | F28: =E28+F27 -> 15.42 | G28: =F28+G27 -> -1169.48 | H28: =G28+H27 -> -2354.38 | I28: =H28+I27 -> -3539.28 | J28: =I28+J27 -> -4724.18 | K28: =J28+K27 -> -5909.08 | ... N28: =M28+N27 -> -9463.78 | O28: =N28 -> -9463.78
B29: 📊 % Poupança Mês | C29: =IF(C23=0,0,C27/C23) -> 0 | D29: =IF(D23=0,0,D27/D23) -> 0.55844205 | E29: =IF(E23=0,0,E27/E23) -> 0 | F29: =IF(F23=0,0,F27/F23) -> 0 | G29: =IF(G23=0,0,G27/G23) -> 0 | H29: =IF(H23=0,0,H27/H23) -> 0 | I29: =IF(I23=0,0,I27/I23) -> 0 | J29: =IF(J23=0,0,J27/J23) -> 0 | ... O29: =IF(O23=0,0,O27/O23) -> -1.4803347
I34: 💸 ONDE VAI O DINHEIRO — POR CATEGORIA
I35: Categoria | J35: Total Ano | K35: % Gasto | L35: % Renda | M35: Alerta
I36: Moradia | J36: =Janeiro!M22+Fevereiro!M22+'Março'!M22+Abril!M22+Maio!M22+Junho!M22+Julho!M22+Agosto!M22+Setembro!M22+Outubro!M22+Novembro!M22+Dezembro!M22 -> 2400 | K36: =IF(H5=0,0,J36/H5) -> 0.15135481 | L36: =IF(E5=0,0,J36/E5) -> 0.37541061 | M36: =IF(L36>0.2,"🔴 Alto",IF(L36>0.1,"🟡 Médio","🟢 OK")) -> 🔴 Alto | N36: Moradia
I37: Alimentação | J37: =Janeiro!M23+Fevereiro!M23+'Março'!M23+Abril!M23+Maio!M23+Junho!M23+Julho!M23+Agosto!M23+Setembro!M23+Outubro!M23+Novembro!M23+Dezembro!M23 -> 584.98 | K37: =IF(H5=0,0,J37/H5) -> 0.036891475 | L37: =IF(E5=0,0,J37/E5) -> 0.091503207 | M37: =IF(L37>0.2,"🔴 Alto",IF(L37>0.1,"🟡 Médio","🟢 OK")) -> 🟢 OK | N37: Alimentação
I38: Transporte | J38: =Janeiro!M24+Fevereiro!M24+'Março'!M24+Abril!M24+Maio!M24+Junho!M24+Julho!M24+Agosto!M24+Setembro!M24+Outubro!M24+Novembro!M24+Dezembro!M24 -> 2510 | K38: =IF(H5=0,0,J38/H5) -> 0.15829191 | L38: =IF(E5=0,0,J38/E5) -> 0.39261692 | M38: =IF(L38>0.2,"🔴 Alto",IF(L38>0.1,"🟡 Médio","🟢 OK")) -> 🔴 Alto | N38: Transporte
I39: Saúde | J39: =Janeiro!M25+Fevereiro!M25+'Março'!M25+Abril!M25+Maio!M25+Junho!M25+Julho!M25+Agosto!M25+Setembro!M25+Outubro!M25+Novembro!M25+Dezembro!M25 -> 101 | K39: =IF(H5=0,0,J39/H5) -> 0.0063695151 | L39: =IF(E5=0,0,J39/E5) -> 0.01579853 | M39: =IF(L39>0.2,"🔴 Alto",IF(L39>0.1,"🟡 Médio","🟢 OK")) -> 🟢 OK | N39: Saúde
I40: Educação | J40: =Janeiro!M26+Fevereiro!M26+'Março'!M26+Abril!M26+Maio!M26+Junho!M26+Julho!M26+Agosto!M26+Setembro!M26+Outubro!M26+Novembro!M26+Dezembro!M26 -> 5640 | K40: =IF(H5=0,0,J40/H5) -> 0.35568381 | L40: =IF(E5=0,0,J40/E5) -> 0.88221492 | M40: =IF(L40>0.2,"🔴 Alto",IF(L40>0.1,"🟡 Médio","🟢 OK")) -> 🔴 Alto | N40: Educação
I41: Lazer / Diversão | J41: =Janeiro!M27+Fevereiro!M27+'Março'!M27+Abril!M27+Maio!M27+Junho!M27+Julho!M27+Agosto!M27+Setembro!M27+Outubro!M27+Novembro!M27+Dezembro!M27 -> 718.8 | K41: =IF(H5=0,0,J41/H5) -> 0.045330767 | L41: =IF(E5=0,0,J41/E5) -> 0.11243548 | M41: =IF(L41>0.2,"🔴 Alto",IF(L41>0.1,"🟡 Médio","🟢 OK")) -> 🟡 Médio | N41: Lazer / Diversão
I42: Vestuário | J42: =Janeiro!M28+Fevereiro!M28+'Março'!M28+Abril!M28+Maio!M28+Junho!M28+Julho!M28+Agosto!M28+Setembro!M28+Outubro!M28+Novembro!M28+Dezembro!M28 -> 142 | K42: =IF(H5=0,0,J42/H5) -> 0.0089551599 | L42: =IF(E5=0,0,J42/E5) -> 0.022211794 | M42: =IF(L42>0.2,"🔴 Alto",IF(L42>0.1,"🟡 Médio","🟢 OK")) -> 🟢 OK | N42: Vestuário
I43: Tecnologia | J43: =Janeiro!M29+Fevereiro!M29+'Março'!M29+Abril!M29+Maio!M29+Junho!M29+Julho!M29+Agosto!M29+Setembro!M29+Outubro!M29+Novembro!M29+Dezembro!M29 -> 1920 | K43: =IF(H5=0,0,J43/H5) -> 0.12108385 | L43: =IF(E5=0,0,J43/E5) -> 0.30032848 | M43: =IF(L43>0.2,"🔴 Alto",IF(L43>0.1,"🟡 Médio","🟢 OK")) -> 🔴 Alto | N43: Tecnologia
I44: Assinaturas | J44: =Janeiro!M30+Fevereiro!M30+'Março'!M30+Abril!M30+Maio!M30+Junho!M30+Julho!M30+Agosto!M30+Setembro!M30+Outubro!M30+Novembro!M30+Dezembro!M30 -> 0 | K44: =IF(H5=0,0,J44/H5) -> 0 | L44: =IF(E5=0,0,J44/E5) -> 0 | M44: =IF(L44>0.2,"🔴 Alto",IF(L44>0.1,"🟡 Médio","🟢 OK")) -> 🟢 OK | N44: Assinaturas
I45: Seguros | J45: =Janeiro!M31+Fevereiro!M31+'Março'!M31+Abril!M31+Maio!M31+Junho!M31+Julho!M31+Agosto!M31+Setembro!M31+Outubro!M31+Novembro!M31+Dezembro!M31 -> 0 | K45: =IF(H5=0,0,J45/H5) -> 0 | L45: =IF(E5=0,0,J45/E5) -> 0 | M45: =IF(L45>0.2,"🔴 Alto",IF(L45>0.1,"🟡 Médio","🟢 OK")) -> 🟢 OK | N45: Seguros
I46: Impostos | J46: =Janeiro!M32+Fevereiro!M32+'Março'!M32+Abril!M32+Maio!M32+Junho!M32+Julho!M32+Agosto!M32+Setembro!M32+Outubro!M32+Novembro!M32+Dezembro!M32 -> 0 | K46: =IF(H5=0,0,J46/H5) -> 0 | L46: =IF(E5=0,0,J46/E5) -> 0 | M46: =IF(L46>0.2,"🔴 Alto",IF(L46>0.1,"🟡 Médio","🟢 OK")) -> 🟢 OK | N46: Impostos
I47: Investimentos | J47: =Janeiro!M33+Fevereiro!M33+'Março'!M33+Abril!M33+Maio!M33+Junho!M33+Julho!M33+Agosto!M33+Setembro!M33+Outubro!M33+Novembro!M33+Dezembro!M33 -> 0 | K47: =IF(H5=0,0,J47/H5) -> 0 | L47: =IF(E5=0,0,J47/E5) -> 0 | M47: =IF(L47>0.2,"🔴 Alto",IF(L47>0.1,"🟡 Médio","🟢 OK")) -> 🟢 OK | N47: Investimentos
I48: Doações | J48: =Janeiro!M34+Fevereiro!M34+'Março'!M34+Abril!M34+Maio!M34+Junho!M34+Julho!M34+Agosto!M34+Setembro!M34+Outubro!M34+Novembro!M34+Dezembro!M34 -> 0 | K48: =IF(H5=0,0,J48/H5) -> 0 | L48: =IF(E5=0,0,J48/E5) -> 0 | M48: =IF(L48>0.2,"🔴 Alto",IF(L48>0.1,"🟡 Médio","🟢 OK")) -> 🟢 OK | N48: Doações
...

Sheet Configuração
B1: ⚙️ CONFIGURAÇÃO — EDITE TUDO EM AZUL
B4: 💰 SEUS DADOS FINANCEIROS — RENDA VARIÁVEL
B5: # | C5: Parâmetro | D5: Valor | E5: Descrição
B6: 1 | C6: Saldo Inicial (todo dinheiro que você tem HOJE) | D6: 0 | E6: Soma de tudo: contas, carteira, poupança, investimentos
B7: 2 | C7: Renda Mensal ESTIMADA (referência para jarros) | D7: 0 | E7: Estimativa — seu real vem das receitas do mês
B8: 3 | C8: Meta: Reserva de Emergência (R$) | D8: 30000 | E8: Ideal = 6x seu custo de vida mensal
B9: 4 | C9: Meta: Patrimônio Investido em 12 meses | D9: 12000 | E9: Quanto quer ter investido no jarro CFL
B10: 5 | C10: Meta: Patrimônio Total em 12 meses | D10: 50000 | E10: Todo seu dinheiro acumulado
B11: 6 | C11: Renda Passiva ATUAL (mensal) | D11: 0 | E11: Quanto já recebe sem trabalhar
B12: 7 | C12: Meta: Renda Passiva em 12 meses | D12: 1000 | E12: Quanto quer receber de renda passiva por mês
B14: 💵 FONTES DE RENDA — CONFIGURE SUAS FONTES
B15: # | C15: Fonte de Receita | D15: Ativa? | E15: Frequência
B16: 1 | C16: Salário CLT | D16: Sim | E16: Mensal fixo
B17: 2 | C17: Freelance / Projetos | D17: Sim | E17: Variável/projeto
B18: 3 | C18: Vendas Online | D18: Não | E18: Variável
B19: 4 | C19: Consultoria | D19: Não | E19: Por demanda
B20: 5 | C20: Rendimentos / Investimentos | D20: Não | E20: Mensal (juros)
B21: 6 | C21: Aluguel Recebido | D21: Não | E21: Mensal fixo
B22: 7 | C22: Comissões | D22: Não | E22: Variável
B23: 8 | C23: Bônus / Participação | D23: Não | E23: Semestral
B24: 9 | C24: Renda Extra / Bico | D24: Não | E24: Esporádico
B25: 10 | C25: Outros | D25: Não | E25: Esporádico
B27: 🏺 PERCENTUAIS DOS JARROS — PERSONALIZE
B28: Jarro | C28: % do Total | D28: Valor Estimado | E28: Regra de Ouro
B29: 🏠 | C29: Necessidades (NEC) | D29: 0.55 | E29: =D7*D29 -> 0 | F29: 💡 Máx 55%! Se ultrapassa, CORTE custos
B30: 💎 | C30: Liberdade Financeira (CFL) | D30: 0.1 | E30: =D7*D30 -> 0 | F30: 💡 SAGRADO — NUNCA gaste, só invista
B31: 🏦 | C31: Poupança LP (PELP) | D31: 0.1 | E31: =D7*D31 -> 0 | F31: 💡 Para compras acima de R$500
B32: 📚 | C32: Educação (EDU) | D32: 0.1 | E32: =D7*D32 -> 0 | F32: 💡 Investir em VOCÊ = melhor ROI
B33: 🎉 | C33: Diversão (DIV) | D33: 0.1 | E33: =D7*D33 -> 0 | F33: 💡 GASTE TUDO todo mês!
B34: 🤝 | C34: Doações (DOA) | D34: 0.05 | E34: =D7*D34 -> 0 | F34: 💡 Doar ativa reciprocidade
B35: ✅ | C35: TOTAL | D35: =SUM(D29:D34) -> 1 | E35: =SUM(E29:E34) -> 0 | F35: =IF(D35=1,"✅ 100%","⚠️ ERRO: deve somar 100%!") -> ✅ 100%
B37: 🔒 CUSTOS FIXOS MENSAIS — REPLICADOS EM TODOS OS MESES AUTOMATICAMENTE
B38: # | C38: Descrição do Custo Fixo | D38: Valor (R$) | E38: Categoria | F38: Vencimento
B39: 1 | C39: Aluguel / Financiamento | E39: Moradia | F39: 5
B40: 2 | C40: Condomínio | E40: Moradia | F40: 10
B41: 3 | C41: IPTU (parcela) | E41: Impostos | F41: 15
B42: 4 | C42: Energia Elétrica | D42: 200 | E42: Moradia | F42: 10
B43: 5 | C43: Água / Saneamento | E43: Moradia | F43: 15
B44: 6 | C44: Gás | E44: Moradia | F44: 20
B45: 7 | C45: Internet | D45: 100 | E45: Tecnologia | F45: 10
...

Sheet Janeiro
B1: 📅 JANEIRO 2026 — CONTROLE COMPLETO
B3: 🏦 SALDO EM TEMPO REAL | F3: 🏺 JARROS DO MÊS
B4: 🔙 | C4: Saldo Inicial | D4: ='Configuração'!D6 -> 0 | E4: =D5 -> 0 | F4: 🏠 | G4: NEC (55%) | H4: =D5*'Configuração'!D29 -> 0
B5: 💵 | C5: Total Entradas | D5: =E29 -> 0 | E5: =D5 -> 0 | F5: 💎 | G5: CFL (10%) | H5: =D5*'Configuração'!D30 -> 0
B6: 🔒 | C6: Despesas Fixas | D6: =E63 -> 1184.9 | F6: 🏦 | G6: PELP (10%) | H6: =D5*'Configuração'!D31 -> 0
B7: 🛒 | C7: Despesas Variáveis | D7: =E102 -> 0 | F7: 📚 | G7: EDU (10%) | H7: =D5*'Configuração'!D32 -> 0 | J7: =H4 -> 0 | M7: =C109 -> 0 | N7: =H4 -> 0
B8: 💸 | C8: Total Saídas | D8: =D6+D7 -> 1184.9 | E8: =IF(D5=0,0,D8/D5) -> 0 | F8: 🎉 | G8: DIV (10%) | H8: =D5*'Configuração'!D33 -> 0 | J8: =H5 -> 0 | M8: =C110 -> 0 | N8: =H5 -> 0
B9: 📈 | C9: Saldo do Mês | D9: =D5-D8 -> -1184.9 | E9: =IF(D5=0,0,D9/D5) -> 0 | F9: 🤝 | G9: DOA (5%) | H9: =D5*'Configuração'!D34 -> 0 | J9: =H6 -> 0 | M9: =C111 -> 0 | N9: =H6 -> 0
B10: 🏦 | C10: SALDO FINAL | D10: =D4+D9 -> -1184.9 | E10: =D10 -> -1184.9 | J10: =H7 -> 0 | M10: =C112 -> 0 | N10: =H7 -> 0
J11: =H8 -> 0 | M11: =C113 -> 0 | N11: =H8 -> 0
B12: 💰 RECEITAS DO MÊS — DE ONDE VEM SEU DINHEIRO | J12: =H9 -> 0 | M12: =C114 -> 0 | N12: =H9 -> 0
B13: # | C13: Data | D13: Descrição da Receita | E13: Valor (R$) | F13: Fonte de Receita | G13: Recebido? | H13: Observação | M13: =C115 -> 0
B14: 1 | M14: =C116 -> 0
B15: 2 | M15: =C117 -> 0
B16: 3 | M16: =C118 -> 0
B17: 4
B18: 5
B19: 6
B20: 7
B21: 8
B22: 9 | M22: =G109 -> 200
B23: 10 | M23: =G110 -> 0
B24: 11 | M24: =G111 -> 200
B25: 12 | M25: =G112 -> 0
B26: 13 | M26: =G113 -> 470
B27: 14 | M27: =G114 -> 59.9
B28: 15 | M28: =G115 -> 0
B29: 💰 | C29: TOTAL RECEITAS DO MÊS | E29: =SUM(E14:E28) -> 0 | M29: =G116 -> 160
M30: =G117 -> 0
B31: 🔒 DESPESAS FIXAS — AUTOMÁTICAS DA CONFIGURAÇÃO (edite valores se precisar) | M31: =G118 -> 0
B32: # | C32: Venc. | D32: Descrição | E32: Valor (R$) | F32: Categoria | G32: Pago? ✅/❌ | H32: Observação | M32: =G119 -> 0
B33: 1 | C33: ='Configuração'!F39 -> 5 | D33: ='Configuração'!C39 -> Aluguel / Financiamento | E33: ='Configuração'!D39 | F33: ='Configuração'!E39 -> Moradia | M33: =G120 -> 0
B34: 2 | C34: ='Configuração'!F40 -> 10 | D34: ='Configuração'!C40 -> Condomínio | E34: ='Configuração'!D40 | F34: ='Configuração'!E40 -> Moradia | M34: =G121 -> 0
B35: 3 | C35: ='Configuração'!F41 -> 15 | D35: ='Configuração'!C41 -> IPTU (parcela) | E35: ='Configuração'!D41 | F35: ='Configuração'!E41 -> Impostos | M35: =G122 -> 0
B36: 4 | C36: ='Configuração'!F42 -> 10 | D36: ='Configuração'!C42 -> Energia Elétrica | E36: ='Configuração'!D42 -> 200 | F36: ='Configuração'!E42 -> Moradia
B37: 5 | C37: ='Configuração'!F43 -> 15 | D37: ='Configuração'!C43 -> Água / Saneamento | E37: ='Configuração'!D43 | F37: ='Configuração'!E43 -> Moradia
B38: 6 | C38: ='Configuração'!F44 -> 20 | D38: ='Configuração'!C44 -> Gás | E38: ='Configuração'!D44 | F38: ='Configuração'!E44 -> Moradia
B39: 7 | C39: ='Configuração'!F45 -> 10 | D39: ='Configuração'!C45 -> Internet | E39: ='Configuração'!D45 -> 100 | F39: ='Configuração'!E45 -> Tecnologia
B40: 8 | C40: ='Configuração'!F46 -> 12 | D40: ='Configuração'!C46 -> Celular | E40: ='Configuração'!D46 -> 60 | F40: ='Configuração'!E46 -> Tecnologia
B41: 9 | C41: ='Configuração'!F47 -> 5 | D41: ='Configuração'!C47 -> Plano de Saúde | E41: ='Configuração'!D47 | F41: ='Configuração'!E47 -> Saúde
...

Sheet Fevereiro
B1: 📅 FEVEREIRO 2026 — CONTROLE COMPLETO
B3: 🏦 SALDO EM TEMPO REAL | F3: 🏺 JARROS DO MÊS
B4: 🔙 | C4: Saldo Inicial | D4: =Janeiro!E10 -> -1184.9 | E4: =D5 -> 6393 | F4: 🏠 | G4: NEC (55%) | H4: =D5*'Configuração'!D29 -> 3516.15
B5: 💵 | C5: Total Entradas | D5: =E29 -> 6393 | E5: =D5 -> 6393 | F5: 💎 | G5: CFL (10%) | H5: =D5*'Configuração'!D30 -> 639.3
B6: 🔒 | C6: Despesas Fixas | D6: =E63 -> 1184.9 | F6: 🏦 | G6: PELP (10%) | H6: =D5*'Configuração'!D31 -> 639.3
B7: 🛒 | C7: Despesas Variáveis | D7: =E102 -> 1637.98 | F7: 📚 | G7: EDU (10%) | H7: =D5*'Configuração'!D32 -> 639.3 | J7: =H4 -> 3516.15 | M7: =C109 -> 0 | N7: =H4 -> 3516.15
B8: 💸 | C8: Total Saídas | D8: =D6+D7 -> 2822.88 | E8: =IF(D5=0,0,D8/D5) -> 0.44155795 | F8: 🎉 | G8: DIV (10%) | H8: =D5*'Configuração'!D33 -> 639.3 | J8: =H5 -> 639.3 | M8: =C110 -> 0 | N8: =H5 -> 639.3
B9: 📈 | C9: Saldo do Mês | D9: =D5-D8 -> 3570.12 | E9: =IF(D5=0,0,D9/D5) -> 0.55844205 | F9: 🤝 | G9: DOA (5%) | H9: =D5*'Configuração'!D34 -> 319.65 | J9: =H6 -> 639.3 | M9: =C111 -> 0 | N9: =H6 -> 639.3
B10: 🏦 | C10: SALDO FINAL | D10: =D4+D9 -> 2385.22 | E10: =D10 -> 2385.22 | J10: =H7 -> 639.3 | M10: =C112 -> 0 | N10: =H7 -> 639.3
J11: =H8 -> 639.3 | M11: =C113 -> 0 | N11: =H8 -> 639.3
B12: 💰 RECEITAS DO MÊS — DE ONDE VEM SEU DINHEIRO | J12: =H9 -> 319.65 | M12: =C114 -> 0 | N12: =H9 -> 319.65
B13: # | C13: Data | D13: Descrição da Receita | E13: Valor (R$) | F13: Fonte de Receita | G13: Recebido? | H13: Observação | M13: =C115 -> 0
B14: 1 | C14: 46358 | D14: Auxilio Maternidade | E14: 4310 | F14: Governo | G14: Sim | H14: Incomum | M14: =C116 -> 0
B15: 2 | C15: 13/02/2026 | D15: Cataliad | E15: 1000 | F15: Cataliad | G15: Sim | H15: Renda variável / mês | M15: =C117 -> 0
B16: 3 | C16: 14/02/2026 | D16: Cataliad (parcela pensemed) | E16: 333 | F16: Cataliad | G16: Sim | H16: Renda variável / mês | M16: =C118 -> 0
B17: 4 | C17: 16/02/2026 | D17: Bolsa família | E17: 750 | F17: Governo | G17: Sim | H17: Renda fixa
B18: 5
B19: 6
B20: 7
B21: 8
B22: 9 | M22: =G109 -> 200
B23: 10 | M23: =G110 -> 584.98
B24: 11 | M24: =G111 -> 310
B25: 12 | M25: =G112 -> 101
B26: 13 | M26: =G113 -> 470
B27: 14 | M27: =G114 -> 59.9
B28: 15 | M28: =G115 -> 142
B29: 💰 | C29: TOTAL RECEITAS DO MÊS | E29: =SUM(E14:E28) -> 6393 | M29: =G116 -> 160
M30: =G117 -> 0
B31: 🔒 DESPESAS FIXAS — AUTOMÁTICAS DA CONFIGURAÇÃO (edite valores se precisar) | M31: =G118 -> 0
B32: # | C32: Venc. | D32: Descrição | E32: Valor (R$) | F32: Categoria | G32: Pago? ✅/❌ | H32: Observação | M32: =G119 -> 0
B33: 1 | C33: ='Configuração'!F39 -> 5 | D33: ='Configuração'!C39 -> Aluguel / Financiamento | E33: ='Configuração'!D39 | F33: ='Configuração'!E39 -> Moradia | M33: =G120 -> 0
B34: 2 | C34: ='Configuração'!F40 -> 10 | D34: ='Configuração'!C40 -> Condomínio | E34: ='Configuração'!D40 | F34: ='Configuração'!E40 -> Moradia | M34: =G121 -> 0
B35: 3 | C35: ='Configuração'!F41 -> 15 | D35: ='Configuração'!C41 -> IPTU (parcela) | E35: ='Configuração'!D41 | F35: ='Configuração'!E41 -> Impostos | M35: =G122 -> 0
B36: 4 | C36: ='Configuração'!F42 -> 10 | D36: ='Configuração'!C42 -> Energia Elétrica | E36: ='Configuração'!D42 -> 200 | F36: ='Configuração'!E42 -> Moradia | G36: ✅
B37: 5 | C37: ='Configuração'!F43 -> 15 | D37: ='Configuração'!C43 -> Água / Saneamento | E37: ='Configuração'!D43 | F37: ='Configuração'!E43 -> Moradia
B38: 6 | C38: ='Configuração'!F44 -> 20 | D38: ='Configuração'!C44 -> Gás | E38: ='Configuração'!D44 | F38: ='Configuração'!E44 -> Moradia
B39: 7 | C39: ='Configuração'!F45 -> 10 | D39: ='Configuração'!C45 -> Internet | E39: ='Configuração'!D45 -> 100 | F39: ='Configuração'!E45 -> Tecnologia | G39: ❌
B40: 8 | C40: ='Configuração'!F46 -> 12 | D40: ='Configuração'!C46 -> Celular | E40: ='Configuração'!D46 -> 60 | F40: ='Configuração'!E46 -> Tecnologia | G40: ❌
B41: 9 | C41: ='Configuração'!F47 -> 5 | D41: ='Configuração'!C47 -> Plano de Saúde | E41: ='Configuração'!D47 | F41: ='Configuração'!E47 -> Saúde
...

Sheet Março
B1: 📅 MARÇO 2026 — CONTROLE COMPLETO
B3: 🏦 SALDO EM TEMPO REAL | F3: 🏺 JARROS DO MÊS
B4: 🔙 | C4: Saldo Inicial | D4: =Fevereiro!E10 -> 2385.22 | E4: =D5 -> 0 | F4: 🏠 | G4: NEC (55%) | H4: =D5*'Configuração'!D29 -> 0
B5: 💵 | C5: Total Entradas | D5: =E29 -> 0 | E5: =D5 -> 0 | F5: 💎 | G5: CFL (10%) | H5: =D5*'Configuração'!D30 -> 0
B6: 🔒 | C6: Despesas Fixas | D6: =E63 -> 1184.9 | F6: 🏦 | G6: PELP (10%) | H6: =D5*'Configuração'!D31 -> 0
B7: 🛒 | C7: Despesas Variáveis | D7: =E102 -> 0 | F7: 📚 | G7: EDU (10%) | H7: =D5*'Configuração'!D32 -> 0 | J7: =H4 -> 0 | M7: =C109 -> 0 | N7: =H4 -> 0
B8: 💸 | C8: Total Saídas | D8: =D6+D7 -> 1184.9 | E8: =IF(D5=0,0,D8/D5) -> 0 | F8: 🎉 | G8: DIV (10%) | H8: =D5*'Configuração'!D33 -> 0 | J8: =H5 -> 0 | M8: =C110 -> 0 | N8: =H5 -> 0
B9: 📈 | C9: Saldo do Mês | D9: =D5-D8 -> -1184.9 | E9: =IF(D5=0,0,D9/D5) -> 0 | F9: 🤝 | G9: DOA (5%) | H9: =D5*'Configuração'!D34 -> 0 | J9: =H6 -> 0 | M9: =C111 -> 0 | N9: =H6 -> 0
B10: 🏦 | C10: SALDO FINAL | D10: =D4+D9 -> 1200.32 | E10: =D10 -> 1200.32 | J10: =H7 -> 0 | M10: =C112 -> 0 | N10: =H7 -> 0
J11: =H8 -> 0 | M11: =C113 -> 0 | N11: =H8 -> 0
B12: 💰 RECEITAS DO MÊS — DE ONDE VEM SEU DINHEIRO | J12: =H9 -> 0 | M12: =C114 -> 0 | N12: =H9 -> 0
B13: # | C13: Data | D13: Descrição da Receita | E13: Valor (R$) | F13: Fonte de Receita | G13: Recebido? | H13: Observação | M13: =C115 -> 0
B14: 1 | M14: =C116 -> 0
B15: 2 | M15: =C117 -> 0
B16: 3 | M16: =C118 -> 0
B17: 4
B18: 5
B19: 6
B20: 7
B21: 8
B22: 9 | M22: =G109 -> 200
B23: 10 | M23: =G110 -> 0
B24: 11 | M24: =G111 -> 200
B25: 12 | M25: =G112 -> 0
B26: 13 | M26: =G113 -> 470
B27: 14 | M27: =G114 -> 59.9
B28: 15 | M28: =G115 -> 0
B29: 💰 | C29: TOTAL RECEITAS DO MÊS | E29: =SUM(E14:E28) -> 0 | M29: =G116 -> 160
M30: =G117 -> 0
B31: 🔒 DESPESAS FIXAS — AUTOMÁTICAS DA CONFIGURAÇÃO (edite valores se precisar) | M31: =G118 -> 0
B32: # | C32: Venc. | D32: Descrição | E32: Valor (R$) | F32: Categoria | G32: Pago? ✅/❌ | H32: Observação | M32: =G119 -> 0
B33: 1 | C33: ='Configuração'!F39 -> 5 | D33: ='Configuração'!C39 -> Aluguel / Financiamento | E33: ='Configuração'!D39 | F33: ='Configuração'!E39 -> Moradia | M33: =G120 -> 0
B34: 2 | C34: ='Configuração'!F40 -> 10 | D34: ='Configuração'!C40 -> Condomínio | E34: ='Configuração'!D40 | F34: ='Configuração'!E40 -> Moradia | M34: =G121 -> 0
B35: 3 | C35: ='Configuração'!F41 -> 15 | D35: ='Configuração'!C41 -> IPTU (parcela) | E35: ='Configuração'!D41 | F35: ='Configuração'!E41 -> Impostos | M35: =G122 -> 0
B36: 4 | C36: ='Configuração'!F42 -> 10 | D36: ='Configuração'!C42 -> Energia Elétrica | E36: ='Configuração'!D42 -> 200 | F36: ='Configuração'!E42 -> Moradia
B37: 5 | C37: ='Configuração'!F43 -> 15 | D37: ='Configuração'!C43 -> Água / Saneamento | E37: ='Configuração'!D43 | F37: ='Configuração'!E43 -> Moradia
B38: 6 | C38: ='Configuração'!F44 -> 20 | D38: ='Configuração'!C44 -> Gás | E38: ='Configuração'!D44 | F38: ='Configuração'!E44 -> Moradia
B39: 7 | C39: ='Configuração'!F45 -> 10 | D39: ='Configuração'!C45 -> Internet | E39: ='Configuração'!D45 -> 100 | F39: ='Configuração'!E45 -> Tecnologia
B40: 8 | C40: ='Configuração'!F46 -> 12 | D40: ='Configuração'!C46 -> Celular | E40: ='Configuração'!D46 -> 60 | F40: ='Configuração'!E46 -> Tecnologia
B41: 9 | C41: ='Configuração'!F47 -> 5 | D41: ='Configuração'!C47 -> Plano de Saúde | E41: ='Configuração'!D47 | F41: ='Configuração'!E47 -> Saúde
...

Sheet Abril
B1: 📅 ABRIL 2026 — CONTROLE COMPLETO
B3: 🏦 SALDO EM TEMPO REAL | F3: 🏺 JARROS DO MÊS
B4: 🔙 | C4: Saldo Inicial | D4: ='Março'!E10 -> 1200.32 | E4: =D5 -> 0 | F4: 🏠 | G4: NEC (55%) | H4: =D5*'Configuração'!D29 -> 0
B5: 💵 | C5: Total Entradas | D5: =E29 -> 0 | E5: =D5 -> 0 | F5: 💎 | G5: CFL (10%) | H5: =D5*'Configuração'!D30 -> 0
B6: 🔒 | C6: Despesas Fixas | D6: =E63 -> 1184.9 | F6: 🏦 | G6: PELP (10%) | H6: =D5*'Configuração'!D31 -> 0
B7: 🛒 | C7: Despesas Variáveis | D7: =E102 -> 0 | F7: 📚 | G7: EDU (10%) | H7: =D5*'Configuração'!D32 -> 0 | J7: =H4 -> 0 | M7: =C109 -> 0 | N7: =H4 -> 0
B8: 💸 | C8: Total Saídas | D8: =D6+D7 -> 1184.9 | E8: =IF(D5=0,0,D8/D5) -> 0 | F8: 🎉 | G8: DIV (10%) | H8: =D5*'Configuração'!D33 -> 0 | J8: =H5 -> 0 | M8: =C110 -> 0 | N8: =H5 -> 0
B9: 📈 | C9: Saldo do Mês | D9: =D5-D8 -> -1184.9 | E9: =IF(D5=0,0,D9/D5) -> 0 | F9: 🤝 | G9: DOA (5%) | H9: =D5*'Configuração'!D34 -> 0 | J9: =H6 -> 0 | M9: =C111 -> 0 | N9: =H6 -> 0
B10: 🏦 | C10: SALDO FINAL | D10: =D4+D9 -> 15.42 | E10: =D10 -> 15.42 | J10: =H7 -> 0 | M10: =C112 -> 0 | N10: =H7 -> 0
J11: =H8 -> 0 | M11: =C113 -> 0 | N11: =H8 -> 0
B12: 💰 RECEITAS DO MÊS — DE ONDE VEM SEU DINHEIRO | J12: =H9 -> 0 | M12: =C114 -> 0 | N12: =H9 -> 0
B13: # | C13: Data | D13: Descrição da Receita | E13: Valor (R$) | F13: Fonte de Receita | G13: Recebido? | H13: Observação | M13: =C115 -> 0
B14: 1 | M14: =C116 -> 0
B15: 2 | M15: =C117 -> 0
B16: 3 | M16: =C118 -> 0
B17: 4
B18: 5
B19: 6
B20: 7
B21: 8
B22: 9 | M22: =G109 -> 200
B23: 10 | M23: =G110 -> 0
B24: 11 | M24: =G111 -> 200
B25: 12 | M25: =G112 -> 0
B26: 13 | M26: =G113 -> 470
B27: 14 | M27: =G114 -> 59.9
B28: 15 | M28: =G115 -> 0
B29: 💰 | C29: TOTAL RECEITAS DO MÊS | E29: =SUM(E14:E28) -> 0 | M29: =G116 -> 160
M30: =G117 -> 0
B31: 🔒 DESPESAS FIXAS — AUTOMÁTICAS DA CONFIGURAÇÃO (edite valores se precisar) | M31: =G118 -> 0
B32: # | C32: Venc. | D32: Descrição | E32: Valor (R$) | F32: Categoria | G32: Pago? ✅/❌ | H32: Observação | M32: =G119 -> 0
B33: 1 | C33: ='Configuração'!F39 -> 5 | D33: ='Configuração'!C39 -> Aluguel / Financiamento | E33: ='Configuração'!D39 | F33: ='Configuração'!E39 -> Moradia | M33: =G120 -> 0
B34: 2 | C34: ='Configuração'!F40 -> 10 | D34: ='Configuração'!C40 -> Condomínio | E34: ='Configuração'!D40 | F34: ='Configuração'!E40 -> Moradia | M34: =G121 -> 0
B35: 3 | C35: ='Configuração'!F41 -> 15 | D35: ='Configuração'!C41 -> IPTU (parcela) | E35: ='Configuração'!D41 | F35: ='Configuração'!E41 -> Impostos | M35: =G122 -> 0
B36: 4 | C36: ='Configuração'!F42 -> 10 | D36: ='Configuração'!C42 -> Energia Elétrica | E36: ='Configuração'!D42 -> 200 | F36: ='Configuração'!E42 -> Moradia
B37: 5 | C37: ='Configuração'!F43 -> 15 | D37: ='Configuração'!C43 -> Água / Saneamento | E37: ='Configuração'!D43 | F37: ='Configuração'!E43 -> Moradia
B38: 6 | C38: ='Configuração'!F44 -> 20 | D38: ='Configuração'!C44 -> Gás | E38: ='Configuração'!D44 | F38: ='Configuração'!E44 -> Moradia
B39: 7 | C39: ='Configuração'!F45 -> 10 | D39: ='Configuração'!C45 -> Internet | E39: ='Configuração'!D45 -> 100 | F39: ='Configuração'!E45 -> Tecnologia
B40: 8 | C40: ='Configuração'!F46 -> 12 | D40: ='Configuração'!C46 -> Celular | E40: ='Configuração'!D46 -> 60 | F40: ='Configuração'!E46 -> Tecnologia
B41: 9 | C41: ='Configuração'!F47 -> 5 | D41: ='Configuração'!C47 -> Plano de Saúde | E41: ='Configuração'!D47 | F41: ='Configuração'!E47 -> Saúde
...

Sheet Maio
B1: 📅 MAIO 2026 — CONTROLE COMPLETO
B3: 🏦 SALDO EM TEMPO REAL | F3: 🏺 JARROS DO MÊS
B4: 🔙 | C4: Saldo Inicial | D4: =Abril!E10 -> 15.42 | E4: =D5 -> 0 | F4: 🏠 | G4: NEC (55%) | H4: =D5*'Configuração'!D29 -> 0
B5: 💵 | C5: Total Entradas | D5: =E29 -> 0 | E5: =D5 -> 0 | F5: 💎 | G5: CFL (10%) | H5: =D5*'Configuração'!D30 -> 0
B6: 🔒 | C6: Despesas Fixas | D6: =E63 -> 1184.9 | F6: 🏦 | G6: PELP (10%) | H6: =D5*'Configuração'!D31 -> 0
B7: 🛒 | C7: Despesas Variáveis | D7: =E102 -> 0 | F7: 📚 | G7: EDU (10%) | H7: =D5*'Configuração'!D32 -> 0 | J7: =H4 -> 0 | M7: =C109 -> 0 | N7: =H4 -> 0
B8: 💸 | C8: Total Saídas | D8: =D6+D7 -> 1184.9 | E8: =IF(D5=0,0,D8/D5) -> 0 | F8: 🎉 | G8: DIV (10%) | H8: =D5*'Configuração'!D33 -> 0 | J8: =H5 -> 0 | M8: =C110 -> 0 | N8: =H5 -> 0
B9: 📈 | C9: Saldo do Mês | D9: =D5-D8 -> -1184.9 | E9: =IF(D5=0,0,D9/D5) -> 0 | F9: 🤝 | G9: DOA (5%) | H9: =D5*'Configuração'!D34 -> 0 | J9: =H6 -> 0 | M9: =C111 -> 0 | N9: =H6 -> 0
B10: 🏦 | C10: SALDO FINAL | D10: =D4+D9 -> -1169.48 | E10: =D10 -> -1169.48 | J10: =H7 -> 0 | M10: =C112 -> 0 | N10: =H7 -> 0
J11: =H8 -> 0 | M11: =C113 -> 0 | N11: =H8 -> 0
B12: 💰 RECEITAS DO MÊS — DE ONDE VEM SEU DINHEIRO | J12: =H9 -> 0 | M12: =C114 -> 0 | N12: =H9 -> 0
B13: # | C13: Data | D13: Descrição da Receita | E13: Valor (R$) | F13: Fonte de Receita | G13: Recebido? | H13: Observação | M13: =C115 -> 0
B14: 1 | M14: =C116 -> 0
B15: 2 | M15: =C117 -> 0
B16: 3 | M16: =C118 -> 0
B17: 4
B18: 5
B19: 6
B20: 7
B21: 8
B22: 9 | M22: =G109 -> 200
B23: 10 | M23: =G110 -> 0
B24: 11 | M24: =G111 -> 200
B25: 12 | M25: =G112 -> 0
B26: 13 | M26: =G113 -> 470
B27: 14 | M27: =G114 -> 59.9
B28: 15 | M28: =G115 -> 0
B29: 💰 | C29: TOTAL RECEITAS DO MÊS | E29: =SUM(E14:E28) -> 0 | M29: =G116 -> 160
M30: =G117 -> 0
B31: 🔒 DESPESAS FIXAS — AUTOMÁTICAS DA CONFIGURAÇÃO (edite valores se precisar) | M31: =G118 -> 0
B32: # | C32: Venc. | D32: Descrição | E32: Valor (R$) | F32: Categoria | G32: Pago? ✅/❌ | H32: Observação | M32: =G119 -> 0
B33: 1 | C33: ='Configuração'!F39 -> 5 | D33: ='Configuração'!C39 -> Aluguel / Financiamento | E33: ='Configuração'!D39 | F33: ='Configuração'!E39 -> Moradia | M33: =G120 -> 0
B34: 2 | C34: ='Configuração'!F40 -> 10 | D34: ='Configuração'!C40 -> Condomínio | E34: ='Configuração'!D40 | F34: ='Configuração'!E40 -> Moradia | M34: =G121 -> 0
B35: 3 | C35: ='Configuração'!F41 -> 15 | D35: ='Configuração'!C41 -> IPTU (parcela) | E35: ='Configuração'!D41 | F35: ='Configuração'!E41 -> Impostos | M35: =G122 -> 0
B36: 4 | C36: ='Configuração'!F42 -> 10 | D36: ='Configuração'!C42 -> Energia Elétrica | E36: ='Configuração'!D42 -> 200 | F36: ='Configuração'!E42 -> Moradia
B37: 5 | C37: ='Configuração'!F43 -> 15 | D37: ='Configuração'!C43 -> Água / Saneamento | E37: ='Configuração'!D43 | F37: ='Configuração'!E43 -> Moradia
B38: 6 | C38: ='Configuração'!F44 -> 20 | D38: ='Configuração'!C44 -> Gás | E38: ='Configuração'!D44 | F38: ='Configuração'!E44 -> Moradia
B39: 7 | C39: ='Configuração'!F45 -> 10 | D39: ='Configuração'!C45 -> Internet | E39: ='Configuração'!D45 -> 100 | F39: ='Configuração'!E45 -> Tecnologia
B40: 8 | C40: ='Configuração'!F46 -> 12 | D40: ='Configuração'!C46 -> Celular | E40: ='Configuração'!D46 -> 60 | F40: ='Configuração'!E46 -> Tecnologia
B41: 9 | C41: ='Configuração'!F47 -> 5 | D41: ='Configuração'!C47 -> Plano de Saúde | E41: ='Configuração'!D47 | F41: ='Configuração'!E47 -> Saúde
...

Sheet Junho
B1: 📅 JUNHO 2026 — CONTROLE COMPLETO
B3: 🏦 SALDO EM TEMPO REAL | F3: 🏺 JARROS DO MÊS
B4: 🔙 | C4: Saldo Inicial | D4: =Maio!E10 -> -1169.48 | E4: =D5 -> 0 | F4: 🏠 | G4: NEC (55%) | H4: =D5*'Configuração'!D29 -> 0
B5: 💵 | C5: Total Entradas | D5: =E29 -> 0 | E5: =D5 -> 0 | F5: 💎 | G5: CFL (10%) | H5: =D5*'Configuração'!D30 -> 0
B6: 🔒 | C6: Despesas Fixas | D6: =E63 -> 1184.9 | F6: 🏦 | G6: PELP (10%) | H6: =D5*'Configuração'!D31 -> 0
B7: 🛒 | C7: Despesas Variáveis | D7: =E102 -> 0 | F7: 📚 | G7: EDU (10%) | H7: =D5*'Configuração'!D32 -> 0 | J7: =H4 -> 0 | M7: =C109 -> 0 | N7: =H4 -> 0
B8: 💸 | C8: Total Saídas | D8: =D6+D7 -> 1184.9 | E8: =IF(D5=0,0,D8/D5) -> 0 | F8: 🎉 | G8: DIV (10%) | H8: =D5*'Configuração'!D33 -> 0 | J8: =H5 -> 0 | M8: =C110 -> 0 | N8: =H5 -> 0
B9: 📈 | C9: Saldo do Mês | D9: =D5-D8 -> -1184.9 | E9: =IF(D5=0,0,D9/D5) -> 0 | F9: 🤝 | G9: DOA (5%) | H9: =D5*'Configuração'!D34 -> 0 | J9: =H6 -> 0 | M9: =C111 -> 0 | N9: =H6 -> 0
B10: 🏦 | C10: SALDO FINAL | D10: =D4+D9 -> -2354.38 | E10: =D10 -> -2354.38 | J10: =H7 -> 0 | M10: =C112 -> 0 | N10: =H7 -> 0
J11: =H8 -> 0 | M11: =C113 -> 0 | N11: =H8 -> 0
B12: 💰 RECEITAS DO MÊS — DE ONDE VEM SEU DINHEIRO | J12: =H9 -> 0 | M12: =C114 -> 0 | N12: =H9 -> 0
B13: # | C13: Data | D13: Descrição da Receita | E13: Valor (R$) | F13: Fonte de Receita | G13: Recebido? | H13: Observação | M13: =C115 -> 0
B14: 1 | M14: =C116 -> 0
B15: 2 | M15: =C117 -> 0
B16: 3 | M16: =C118 -> 0
B17: 4
B18: 5
B19: 6
B20: 7
B21: 8
B22: 9 | M22: =G109 -> 200
B23: 10 | M23: =G110 -> 0
B24: 11 | M24: =G111 -> 200
B25: 12 | M25: =G112 -> 0
B26: 13 | M26: =G113 -> 470
B27: 14 | M27: =G114 -> 59.9
B28: 15 | M28: =G115 -> 0
B29: 💰 | C29: TOTAL RECEITAS DO MÊS | E29: =SUM(E14:E28) -> 0 | M29: =G116 -> 160
M30: =G117 -> 0
B31: 🔒 DESPESAS FIXAS — AUTOMÁTICAS DA CONFIGURAÇÃO (edite valores se precisar) | M31: =G118 -> 0
B32: # | C32: Venc. | D32: Descrição | E32: Valor (R$) | F32: Categoria | G32: Pago? ✅/❌ | H32: Observação | M32: =G119 -> 0
B33: 1 | C33: ='Configuração'!F39 -> 5 | D33: ='Configuração'!C39 -> Aluguel / Financiamento | E33: ='Configuração'!D39 | F33: ='Configuração'!E39 -> Moradia | M33: =G120 -> 0
B34: 2 | C34: ='Configuração'!F40 -> 10 | D34: ='Configuração'!C40 -> Condomínio | E34: ='Configuração'!D40 | F34: ='Configuração'!E40 -> Moradia | M34: =G121 -> 0
B35: 3 | C35: ='Configuração'!F41 -> 15 | D35: ='Configuração'!C41 -> IPTU (parcela) | E35: ='Configuração'!D41 | F35: ='Configuração'!E41 -> Impostos | M35: =G122 -> 0
B36: 4 | C36: ='Configuração'!F42 -> 10 | D36: ='Configuração'!C42 -> Energia Elétrica | E36: ='Configuração'!D42 -> 200 | F36: ='Configuração'!E42 -> Moradia
B37: 5 | C37: ='Configuração'!F43 -> 15 | D37: ='Configuração'!C43 -> Água / Saneamento | E37: ='Configuração'!D43 | F37: ='Configuração'!E43 -> Moradia
B38: 6 | C38: ='Configuração'!F44 -> 20 | D38: ='Configuração'!C44 -> Gás | E38: ='Configuração'!D44 | F38: ='Configuração'!E44 -> Moradia
B39: 7 | C39: ='Configuração'!F45 -> 10 | D39: ='Configuração'!C45 -> Internet | E39: ='Configuração'!D45 -> 100 | F39: ='Configuração'!E45 -> Tecnologia
B40: 8 | C40: ='Configuração'!F46 -> 12 | D40: ='Configuração'!C46 -> Celular | E40: ='Configuração'!D46 -> 60 | F40: ='Configuração'!E46 -> Tecnologia
B41: 9 | C41: ='Configuração'!F47 -> 5 | D41: ='Configuração'!C47 -> Plano de Saúde | E41: ='Configuração'!D47 | F41: ='Configuração'!E47 -> Saúde
...

Sheet Julho
B1: 📅 JULHO 2026 — CONTROLE COMPLETO
B3: 🏦 SALDO EM TEMPO REAL | F3: 🏺 JARROS DO MÊS
B4: 🔙 | C4: Saldo Inicial | D4: =Junho!E10 -> -2354.38 | E4: =D5 -> 0 | F4: 🏠 | G4: NEC (55%) | H4: =D5*'Configuração'!D29 -> 0
B5: 💵 | C5: Total Entradas | D5: =E29 -> 0 | E5: =D5 -> 0 | F5: 💎 | G5: CFL (10%) | H5: =D5*'Configuração'!D30 -> 0
B6: 🔒 | C6: Despesas Fixas | D6: =E63 -> 1184.9 | F6: 🏦 | G6: PELP (10%) | H6: =D5*'Configuração'!D31 -> 0
B7: 🛒 | C7: Despesas Variáveis | D7: =E102 -> 0 | F7: 📚 | G7: EDU (10%) | H7: =D5*'Configuração'!D32 -> 0 | J7: =H4 -> 0 | M7: =C109 -> 0 | N7: =H4 -> 0
B8: 💸 | C8: Total Saídas | D8: =D6+D7 -> 1184.9 | E8: =IF(D5=0,0,D8/D5) -> 0 | F8: 🎉 | G8: DIV (10%) | H8: =D5*'Configuração'!D33 -> 0 | J8: =H5 -> 0 | M8: =C110 -> 0 | N8: =H5 -> 0
B9: 📈 | C9: Saldo do Mês | D9: =D5-D8 -> -1184.9 | E9: =IF(D5=0,0,D9/D5) -> 0 | F9: 🤝 | G9: DOA (5%) | H9: =D5*'Configuração'!D34 -> 0 | J9: =H6 -> 0 | M9: =C111 -> 0 | N9: =H6 -> 0
B10: 🏦 | C10: SALDO FINAL | D10: =D4+D9 -> -3539.28 | E10: =D10 -> -3539.28 | J10: =H7 -> 0 | M10: =C112 -> 0 | N10: =H7 -> 0
J11: =H8 -> 0 | M11: =C113 -> 0 | N11: =H8 -> 0
B12: 💰 RECEITAS DO MÊS — DE ONDE VEM SEU DINHEIRO | J12: =H9 -> 0 | M12: =C114 -> 0 | N12: =H9 -> 0
B13: # | C13: Data | D13: Descrição da Receita | E13: Valor (R$) | F13: Fonte de Receita | G13: Recebido? | H13: Observação | M13: =C115 -> 0
B14: 1 | M14: =C116 -> 0
B15: 2 | M15: =C117 -> 0
B16: 3 | M16: =C118 -> 0
B17: 4
B18: 5
B19: 6
B20: 7
B21: 8
B22: 9 | M22: =G109 -> 200
B23: 10 | M23: =G110 -> 0
B24: 11 | M24: =G111 -> 200
B25: 12 | M25: =G112 -> 0
B26: 13 | M26: =G113 -> 470
B27: 14 | M27: =G114 -> 59.9
B28: 15 | M28: =G115 -> 0
B29: 💰 | C29: TOTAL RECEITAS DO MÊS | E29: =SUM(E14:E28) -> 0 | M29: =G116 -> 160
M30: =G117 -> 0
B31: 🔒 DESPESAS FIXAS — AUTOMÁTICAS DA CONFIGURAÇÃO (edite valores se precisar) | M31: =G118 -> 0
B32: # | C32: Venc. | D32: Descrição | E32: Valor (R$) | F32: Categoria | G32: Pago? ✅/❌ | H32: Observação | M32: =G119 -> 0
B33: 1 | C33: ='Configuração'!F39 -> 5 | D33: ='Configuração'!C39 -> Aluguel / Financiamento | E33: ='Configuração'!D39 | F33: ='Configuração'!E39 -> Moradia | M33: =G120 -> 0
B34: 2 | C34: ='Configuração'!F40 -> 10 | D34: ='Configuração'!C40 -> Condomínio | E34: ='Configuração'!D40 | F34: ='Configuração'!E40 -> Moradia | M34: =G121 -> 0
B35: 3 | C35: ='Configuração'!F41 -> 15 | D35: ='Configuração'!C41 -> IPTU (parcela) | E35: ='Configuração'!D41 | F35: ='Configuração'!E41 -> Impostos | M35: =G122 -> 0
B36: 4 | C36: ='Configuração'!F42 -> 10 | D36: ='Configuração'!C42 -> Energia Elétrica | E36: ='Configuração'!D42 -> 200 | F36: ='Configuração'!E42 -> Moradia
B37: 5 | C37: ='Configuração'!F43 -> 15 | D37: ='Configuração'!C43 -> Água / Saneamento | E37: ='Configuração'!D43 | F37: ='Configuração'!E43 -> Moradia
B38: 6 | C38: ='Configuração'!F44 -> 20 | D38: ='Configuração'!C44 -> Gás | E38: ='Configuração'!D44 | F38: ='Configuração'!E44 -> Moradia
B39: 7 | C39: ='Configuração'!F45 -> 10 | D39: ='Configuração'!C45 -> Internet | E39: ='Configuração'!D45 -> 100 | F39: ='Configuração'!E45 -> Tecnologia
B40: 8 | C40: ='Configuração'!F46 -> 12 | D40: ='Configuração'!C46 -> Celular | E40: ='Configuração'!D46 -> 60 | F40: ='Configuração'!E46 -> Tecnologia
B41: 9 | C41: ='Configuração'!F47 -> 5 | D41: ='Configuração'!C47 -> Plano de Saúde | E41: ='Configuração'!D47 | F41: ='Configuração'!E47 -> Saúde
...

Sheet Agosto
B1: 📅 AGOSTO 2026 — CONTROLE COMPLETO
B3: 🏦 SALDO EM TEMPO REAL | F3: 🏺 JARROS DO MÊS
B4: 🔙 | C4: Saldo Inicial | D4: =Julho!E10 -> -3539.28 | E4: =D5 -> 0 | F4: 🏠 | G4: NEC (55%) | H4: =D5*'Configuração'!D29 -> 0
B5: 💵 | C5: Total Entradas | D5: =E29 -> 0 | E5: =D5 -> 0 | F5: 💎 | G5: CFL (10%) | H5: =D5*'Configuração'!D30 -> 0
B6: 🔒 | C6: Despesas Fixas | D6: =E63 -> 1184.9 | F6: 🏦 | G6: PELP (10%) | H6: =D5*'Configuração'!D31 -> 0
B7: 🛒 | C7: Despesas Variáveis | D7: =E102 -> 0 | F7: 📚 | G7: EDU (10%) | H7: =D5*'Configuração'!D32 -> 0 | J7: =H4 -> 0 | M7: =C109 -> 0 | N7: =H4 -> 0
B8: 💸 | C8: Total Saídas | D8: =D6+D7 -> 1184.9 | E8: =IF(D5=0,0,D8/D5) -> 0 | F8: 🎉 | G8: DIV (10%) | H8: =D5*'Configuração'!D33 -> 0 | J8: =H5 -> 0 | M8: =C110 -> 0 | N8: =H5 -> 0
B9: 📈 | C9: Saldo do Mês | D9: =D5-D8 -> -1184.9 | E9: =IF(D5=0,0,D9/D5) -> 0 | F9: 🤝 | G9: DOA (5%) | H9: =D5*'Configuração'!D34 -> 0 | J9: =H6 -> 0 | M9: =C111 -> 0 | N9: =H6 -> 0
B10: 🏦 | C10: SALDO FINAL | D10: =D4+D9 -> -4724.18 | E10: =D10 -> -4724.18 | J10: =H7 -> 0 | M10: =C112 -> 0 | N10: =H7 -> 0
J11: =H8 -> 0 | M11: =C113 -> 0 | N11: =H8 -> 0
B12: 💰 RECEITAS DO MÊS — DE ONDE VEM SEU DINHEIRO | J12: =H9 -> 0 | M12: =C114 -> 0 | N12: =H9 -> 0
B13: # | C13: Data | D13: Descrição da Receita | E13: Valor (R$) | F13: Fonte de Receita | G13: Recebido? | H13: Observação | M13: =C115 -> 0
B14: 1 | M14: =C116 -> 0
B15: 2 | M15: =C117 -> 0
B16: 3 | M16: =C118 -> 0
B17: 4
B18: 5
B19: 6
B20: 7
B21: 8
B22: 9 | M22: =G109 -> 200
B23: 10 | M23: =G110 -> 0
B24: 11 | M24: =G111 -> 200
B25: 12 | M25: =G112 -> 0
B26: 13 | M26: =G113 -> 470
B27: 14 | M27: =G114 -> 59.9
B28: 15 | M28: =G115 -> 0
B29: 💰 | C29: TOTAL RECEITAS DO MÊS | E29: =SUM(E14:E28) -> 0 | M29: =G116 -> 160
M30: =G117 -> 0
B31: 🔒 DESPESAS FIXAS — AUTOMÁTICAS DA CONFIGURAÇÃO (edite valores se precisar) | M31: =G118 -> 0
B32: # | C32: Venc. | D32: Descrição | E32: Valor (R$) | F32: Categoria | G32: Pago? ✅/❌ | H32: Observação | M32: =G119 -> 0
B33: 1 | C33: ='Configuração'!F39 -> 5 | D33: ='Configuração'!C39 -> Aluguel / Financiamento | E33: ='Configuração'!D39 | F33: ='Configuração'!E39 -> Moradia | M33: =G120 -> 0
B34: 2 | C34: ='Configuração'!F40 -> 10 | D34: ='Configuração'!C40 -> Condomínio | E34: ='Configuração'!D40 | F34: ='Configuração'!E40 -> Moradia | M34: =G121 -> 0
B35: 3 | C35: ='Configuração'!F41 -> 15 | D35: ='Configuração'!C41 -> IPTU (parcela) | E35: ='Configuração'!D41 | F35: ='Configuração'!E41 -> Impostos | M35: =G122 -> 0
B36: 4 | C36: ='Configuração'!F42 -> 10 | D36: ='Configuração'!C42 -> Energia Elétrica | E36: ='Configuração'!D42 -> 200 | F36: ='Configuração'!E42 -> Moradia
B37: 5 | C37: ='Configuração'!F43 -> 15 | D37: ='Configuração'!C43 -> Água / Saneamento | E37: ='Configuração'!D43 | F37: ='Configuração'!E43 -> Moradia
B38: 6 | C38: ='Configuração'!F44 -> 20 | D38: ='Configuração'!C44 -> Gás | E38: ='Configuração'!D44 | F38: ='Configuração'!E44 -> Moradia
B39: 7 | C39: ='Configuração'!F45 -> 10 | D39: ='Configuração'!C45 -> Internet | E39: ='Configuração'!D45 -> 100 | F39: ='Configuração'!E45 -> Tecnologia
B40: 8 | C40: ='Configuração'!F46 -> 12 | D40: ='Configuração'!C46 -> Celular | E40: ='Configuração'!D46 -> 60 | F40: ='Configuração'!E46 -> Tecnologia
B41: 9 | C41: ='Configuração'!F47 -> 5 | D41: ='Configuração'!C47 -> Plano de Saúde | E41: ='Configuração'!D47 | F41: ='Configuração'!E47 -> Saúde
...

Sheet Setembro
B1: 📅 SETEMBRO 2026 — CONTROLE COMPLETO
B3: 🏦 SALDO EM TEMPO REAL | F3: 🏺 JARROS DO MÊS
B4: 🔙 | C4: Saldo Inicial | D4: =Agosto!E10 -> -4724.18 | E4: =D5 -> 0 | F4: 🏠 | G4: NEC (55%) | H4: =D5*'Configuração'!D29 -> 0
B5: 💵 | C5: Total Entradas | D5: =E29 -> 0 | E5: =D5 -> 0 | F5: 💎 | G5: CFL (10%) | H5: =D5*'Configuração'!D30 -> 0
B6: 🔒 | C6: Despesas Fixas | D6: =E63 -> 1184.9 | F6: 🏦 | G6: PELP (10%) | H6: =D5*'Configuração'!D31 -> 0
B7: 🛒 | C7: Despesas Variáveis | D7: =E102 -> 0 | F7: 📚 | G7: EDU (10%) | H7: =D5*'Configuração'!D32 -> 0 | J7: =H4 -> 0 | M7: =C109 -> 0 | N7: =H4 -> 0
B8: 💸 | C8: Total Saídas | D8: =D6+D7 -> 1184.9 | E8: =IF(D5=0,0,D8/D5) -> 0 | F8: 🎉 | G8: DIV (10%) | H8: =D5*'Configuração'!D33 -> 0 | J8: =H5 -> 0 | M8: =C110 -> 0 | N8: =H5 -> 0
B9: 📈 | C9: Saldo do Mês | D9: =D5-D8 -> -1184.9 | E9: =IF(D5=0,0,D9/D5) -> 0 | F9: 🤝 | G9: DOA (5%) | H9: =D5*'Configuração'!D34 -> 0 | J9: =H6 -> 0 | M9: =C111 -> 0 | N9: =H6 -> 0
B10: 🏦 | C10: SALDO FINAL | D10: =D4+D9 -> -5909.08 | E10: =D10 -> -5909.08 | J10: =H7 -> 0 | M10: =C112 -> 0 | N10: =H7 -> 0
J11: =H8 -> 0 | M11: =C113 -> 0 | N11: =H8 -> 0
B12: 💰 RECEITAS DO MÊS — DE ONDE VEM SEU DINHEIRO | J12: =H9 -> 0 | M12: =C114 -> 0 | N12: =H9 -> 0
B13: # | C13: Data | D13: Descrição da Receita | E13: Valor (R$) | F13: Fonte de Receita | G13: Recebido? | H13: Observação | M13: =C115 -> 0
B14: 1 | M14: =C116 -> 0
B15: 2 | M15: =C117 -> 0
B16: 3 | M16: =C118 -> 0
B17: 4
B18: 5
B19: 6
B20: 7
B21: 8
B22: 9 | M22: =G109 -> 200
B23: 10 | M23: =G110 -> 0
B24: 11 | M24: =G111 -> 200
B25: 12 | M25: =G112 -> 0
B26: 13 | M26: =G113 -> 470
B27: 14 | M27: =G114 -> 59.9
B28: 15 | M28: =G115 -> 0
B29: 💰 | C29: TOTAL RECEITAS DO MÊS | E29: =SUM(E14:E28) -> 0 | M29: =G116 -> 160
M30: =G117 -> 0
B31: 🔒 DESPESAS FIXAS — AUTOMÁTICAS DA CONFIGURAÇÃO (edite valores se precisar) | M31: =G118 -> 0
B32: # | C32: Venc. | D32: Descrição | E32: Valor (R$) | F32: Categoria | G32: Pago? ✅/❌ | H32: Observação | M32: =G119 -> 0
B33: 1 | C33: ='Configuração'!F39 -> 5 | D33: ='Configuração'!C39 -> Aluguel / Financiamento | E33: ='Configuração'!D39 | F33: ='Configuração'!E39 -> Moradia | M33: =G120 -> 0
B34: 2 | C34: ='Configuração'!F40 -> 10 | D34: ='Configuração'!C40 -> Condomínio | E34: ='Configuração'!D40 | F34: ='Configuração'!E40 -> Moradia | M34: =G121 -> 0
B35: 3 | C35: ='Configuração'!F41 -> 15 | D35: ='Configuração'!C41 -> IPTU (parcela) | E35: ='Configuração'!D41 | F35: ='Configuração'!E41 -> Impostos | M35: =G122 -> 0
B36: 4 | C36: ='Configuração'!F42 -> 10 | D36: ='Configuração'!C42 -> Energia Elétrica | E36: ='Configuração'!D42 -> 200 | F36: ='Configuração'!E42 -> Moradia
B37: 5 | C37: ='Configuração'!F43 -> 15 | D37: ='Configuração'!C43 -> Água / Saneamento | E37: ='Configuração'!D43 | F37: ='Configuração'!E43 -> Moradia
B38: 6 | C38: ='Configuração'!F44 -> 20 | D38: ='Configuração'!C44 -> Gás | E38: ='Configuração'!D44 | F38: ='Configuração'!E44 -> Moradia
B39: 7 | C39: ='Configuração'!F45 -> 10 | D39: ='Configuração'!C45 -> Internet | E39: ='Configuração'!D45 -> 100 | F39: ='Configuração'!E45 -> Tecnologia
B40: 8 | C40: ='Configuração'!F46 -> 12 | D40: ='Configuração'!C46 -> Celular | E40: ='Configuração'!D46 -> 60 | F40: ='Configuração'!E46 -> Tecnologia
B41: 9 | C41: ='Configuração'!F47 -> 5 | D41: ='Configuração'!C47 -> Plano de Saúde | E41: ='Configuração'!D47 | F41: ='Configuração'!E47 -> Saúde
...

Sheet Outubro
B1: 📅 OUTUBRO 2026 — CONTROLE COMPLETO
B3: 🏦 SALDO EM TEMPO REAL | F3: 🏺 JARROS DO MÊS
B4: 🔙 | C4: Saldo Inicial | D4: =Setembro!E10 -> -5909.08 | E4: =D5 -> 0 | F4: 🏠 | G4: NEC (55%) | H4: =D5*'Configuração'!D29 -> 0
B5: 💵 | C5: Total Entradas | D5: =E29 -> 0 | E5: =D5 -> 0 | F5: 💎 | G5: CFL (10%) | H5: =D5*'Configuração'!D30 -> 0
B6: 🔒 | C6: Despesas Fixas | D6: =E63 -> 1184.9 | F6: 🏦 | G6: PELP (10%) | H6: =D5*'Configuração'!D31 -> 0
B7: 🛒 | C7: Despesas Variáveis | D7: =E102 -> 0 | F7: 📚 | G7: EDU (10%) | H7: =D5*'Configuração'!D32 -> 0 | J7: =H4 -> 0 | M7: =C109 -> 0 | N7: =H4 -> 0
B8: 💸 | C8: Total Saídas | D8: =D6+D7 -> 1184.9 | E8: =IF(D5=0,0,D8/D5) -> 0 | F8: 🎉 | G8: DIV (10%) | H8: =D5*'Configuração'!D33 -> 0 | J8: =H5 -> 0 | M8: =C110 -> 0 | N8: =H5 -> 0
B9: 📈 | C9: Saldo do Mês | D9: =D5-D8 -> -1184.9 | E9: =IF(D5=0,0,D9/D5) -> 0 | F9: 🤝 | G9: DOA (5%) | H9: =D5*'Configuração'!D34 -> 0 | J9: =H6 -> 0 | M9: =C111 -> 0 | N9: =H6 -> 0
B10: 🏦 | C10: SALDO FINAL | D10: =D4+D9 -> -7093.98 | E10: =D10 -> -7093.98 | J10: =H7 -> 0 | M10: =C112 -> 0 | N10: =H7 -> 0
J11: =H8 -> 0 | M11: =C113 -> 0 | N11: =H8 -> 0
B12: 💰 RECEITAS DO MÊS — DE ONDE VEM SEU DINHEIRO | J12: =H9 -> 0 | M12: =C114 -> 0 | N12: =H9 -> 0
B13: # | C13: Data | D13: Descrição da Receita | E13: Valor (R$) | F13: Fonte de Receita | G13: Recebido? | H13: Observação | M13: =C115 -> 0
B14: 1 | M14: =C116 -> 0
B15: 2 | M15: =C117 -> 0
B16: 3 | M16: =C118 -> 0
B17: 4
B18: 5
B19: 6
B20: 7
B21: 8
B22: 9 | M22: =G109 -> 200
B23: 10 | M23: =G110 -> 0
B24: 11 | M24: =G111 -> 200
B25: 12 | M25: =G112 -> 0
B26: 13 | M26: =G113 -> 470
B27: 14 | M27: =G114 -> 59.9
B28: 15 | M28: =G115 -> 0
B29: 💰 | C29: TOTAL RECEITAS DO MÊS | E29: =SUM(E14:E28) -> 0 | M29: =G116 -> 160
M30: =G117 -> 0
B31: 🔒 DESPESAS FIXAS — AUTOMÁTICAS DA CONFIGURAÇÃO (edite valores se precisar) | M31: =G118 -> 0
B32: # | C32: Venc. | D32: Descrição | E32: Valor (R$) | F32: Categoria | G32: Pago? ✅/❌ | H32: Observação | M32: =G119 -> 0
B33: 1 | C33: ='Configuração'!F39 -> 5 | D33: ='Configuração'!C39 -> Aluguel / Financiamento | E33: ='Configuração'!D39 | F33: ='Configuração'!E39 -> Moradia | M33: =G120 -> 0
B34: 2 | C34: ='Configuração'!F40 -> 10 | D34: ='Configuração'!C40 -> Condomínio | E34: ='Configuração'!D40 | F34: ='Configuração'!E40 -> Moradia | M34: =G121 -> 0
B35: 3 | C35: ='Configuração'!F41 -> 15 | D35: ='Configuração'!C41 -> IPTU (parcela) | E35: ='Configuração'!D41 | F35: ='Configuração'!E41 -> Impostos | M35: =G122 -> 0
B36: 4 | C36: ='Configuração'!F42 -> 10 | D36: ='Configuração'!C42 -> Energia Elétrica | E36: ='Configuração'!D42 -> 200 | F36: ='Configuração'!E42 -> Moradia
B37: 5 | C37: ='Configuração'!F43 -> 15 | D37: ='Configuração'!C43 -> Água / Saneamento | E37: ='Configuração'!D43 | F37: ='Configuração'!E43 -> Moradia
B38: 6 | C38: ='Configuração'!F44 -> 20 | D38: ='Configuração'!C44 -> Gás | E38: ='Configuração'!D44 | F38: ='Configuração'!E44 -> Moradia
B39: 7 | C39: ='Configuração'!F45 -> 10 | D39: ='Configuração'!C45 -> Internet | E39: ='Configuração'!D45 -> 100 | F39: ='Configuração'!E45 -> Tecnologia
B40: 8 | C40: ='Configuração'!F46 -> 12 | D40: ='Configuração'!C46 -> Celular | E40: ='Configuração'!D46 -> 60 | F40: ='Configuração'!E46 -> Tecnologia
B41: 9 | C41: ='Configuração'!F47 -> 5 | D41: ='Configuração'!C47 -> Plano de Saúde | E41: ='Configuração'!D47 | F41: ='Configuração'!E47 -> Saúde
...

Sheet Novembro
B1: 📅 NOVEMBRO 2026 — CONTROLE COMPLETO
B3: 🏦 SALDO EM TEMPO REAL | F3: 🏺 JARROS DO MÊS
B4: 🔙 | C4: Saldo Inicial | D4: =Outubro!E10 -> -7093.98 | E4: =D5 -> 0 | F4: 🏠 | G4: NEC (55%) | H4: =D5*'Configuração'!D29 -> 0
B5: 💵 | C5: Total Entradas | D5: =E29 -> 0 | E5: =D5 -> 0 | F5: 💎 | G5: CFL (10%) | H5: =D5*'Configuração'!D30 -> 0
B6: 🔒 | C6: Despesas Fixas | D6: =E63 -> 1184.9 | F6: 🏦 | G6: PELP (10%) | H6: =D5*'Configuração'!D31 -> 0
B7: 🛒 | C7: Despesas Variáveis | D7: =E102 -> 0 | F7: 📚 | G7: EDU (10%) | H7: =D5*'Configuração'!D32 -> 0 | J7: =H4 -> 0 | M7: =C109 -> 0 | N7: =H4 -> 0
B8: 💸 | C8: Total Saídas | D8: =D6+D7 -> 1184.9 | E8: =IF(D5=0,0,D8/D5) -> 0 | F8: 🎉 | G8: DIV (10%) | H8: =D5*'Configuração'!D33 -> 0 | J8: =H5 -> 0 | M8: =C110 -> 0 | N8: =H5 -> 0
B9: 📈 | C9: Saldo do Mês | D9: =D5-D8 -> -1184.9 | E9: =IF(D5=0,0,D9/D5) -> 0 | F9: 🤝 | G9: DOA (5%) | H9: =D5*'Configuração'!D34 -> 0 | J9: =H6 -> 0 | M9: =C111 -> 0 | N9: =H6 -> 0
B10: 🏦 | C10: SALDO FINAL | D10: =D4+D9 -> -8278.88 | E10: =D10 -> -8278.88 | J10: =H7 -> 0 | M10: =C112 -> 0 | N10: =H7 -> 0
J11: =H8 -> 0 | M11: =C113 -> 0 | N11: =H8 -> 0
B12: 💰 RECEITAS DO MÊS — DE ONDE VEM SEU DINHEIRO | J12: =H9 -> 0 | M12: =C114 -> 0 | N12: =H9 -> 0
B13: # | C13: Data | D13: Descrição da Receita | E13: Valor (R$) | F13: Fonte de Receita | G13: Recebido? | H13: Observação | M13: =C115 -> 0
B14: 1 | M14: =C116 -> 0
B15: 2 | M15: =C117 -> 0
B16: 3 | M16: =C118 -> 0
B17: 4
B18: 5
B19: 6
B20: 7
B21: 8
B22: 9 | M22: =G109 -> 200
B23: 10 | M23: =G110 -> 0
B24: 11 | M24: =G111 -> 200
B25: 12 | M25: =G112 -> 0
B26: 13 | M26: =G113 -> 470
B27: 14 | M27: =G114 -> 59.9
B28: 15 | M28: =G115 -> 0
B29: 💰 | C29: TOTAL RECEITAS DO MÊS | E29: =SUM(E14:E28) -> 0 | M29: =G116 -> 160
M30: =G117 -> 0
B31: 🔒 DESPESAS FIXAS — AUTOMÁTICAS DA CONFIGURAÇÃO (edite valores se precisar) | M31: =G118 -> 0
B32: # | C32: Venc. | D32: Descrição | E32: Valor (R$) | F32: Categoria | G32: Pago? ✅/❌ | H32: Observação | M32: =G119 -> 0
B33: 1 | C33: ='Configuração'!F39 -> 5 | D33: ='Configuração'!C39 -> Aluguel / Financiamento | E33: ='Configuração'!D39 | F33: ='Configuração'!E39 -> Moradia | M33: =G120 -> 0
B34: 2 | C34: ='Configuração'!F40 -> 10 | D34: ='Configuração'!C40 -> Condomínio | E34: ='Configuração'!D40 | F34: ='Configuração'!E40 -> Moradia | M34: =G121 -> 0
B35: 3 | C35: ='Configuração'!F41 -> 15 | D35: ='Configuração'!C41 -> IPTU (parcela) | E35: ='Configuração'!D41 | F35: ='Configuração'!E41 -> Impostos | M35: =G122 -> 0
B36: 4 | C36: ='Configuração'!F42 -> 10 | D36: ='Configuração'!C42 -> Energia Elétrica | E36: ='Configuração'!D42 -> 200 | F36: ='Configuração'!E42 -> Moradia
B37: 5 | C37: ='Configuração'!F43 -> 15 | D37: ='Configuração'!C43 -> Água / Saneamento | E37: ='Configuração'!D43 | F37: ='Configuração'!E43 -> Moradia
B38: 6 | C38: ='Configuração'!F44 -> 20 | D38: ='Configuração'!C44 -> Gás | E38: ='Configuração'!D44 | F38: ='Configuração'!E44 -> Moradia
B39: 7 | C39: ='Configuração'!F45 -> 10 | D39: ='Configuração'!C45 -> Internet | E39: ='Configuração'!D45 -> 100 | F39: ='Configuração'!E45 -> Tecnologia
B40: 8 | C40: ='Configuração'!F46 -> 12 | D40: ='Configuração'!C46 -> Celular | E40: ='Configuração'!D46 -> 60 | F40: ='Configuração'!E46 -> Tecnologia
B41: 9 | C41: ='Configuração'!F47 -> 5 | D41: ='Configuração'!C47 -> Plano de Saúde | E41: ='Configuração'!D47 | F41: ='Configuração'!E47 -> Saúde
...

Sheet Dezembro
B1: 📅 DEZEMBRO 2026 — CONTROLE COMPLETO
B3: 🏦 SALDO EM TEMPO REAL | F3: 🏺 JARROS DO MÊS
B4: 🔙 | C4: Saldo Inicial | D4: =Novembro!E10 -> -8278.88 | E4: =D5 -> 0 | F4: 🏠 | G4: NEC (55%) | H4: =D5*'Configuração'!D29 -> 0
B5: 💵 | C5: Total Entradas | D5: =E29 -> 0 | E5: =D5 -> 0 | F5: 💎 | G5: CFL (10%) | H5: =D5*'Configuração'!D30 -> 0
B6: 🔒 | C6: Despesas Fixas | D6: =E63 -> 1184.9 | F6: 🏦 | G6: PELP (10%) | H6: =D5*'Configuração'!D31 -> 0
B7: 🛒 | C7: Despesas Variáveis | D7: =E102 -> 0 | F7: 📚 | G7: EDU (10%) | H7: =D5*'Configuração'!D32 -> 0 | J7: =H4 -> 0 | M7: =C109 -> 0 | N7: =H4 -> 0
B8: 💸 | C8: Total Saídas | D8: =D6+D7 -> 1184.9 | E8: =IF(D5=0,0,D8/D5) -> 0 | F8: 🎉 | G8: DIV (10%) | H8: =D5*'Configuração'!D33 -> 0 | J8: =H5 -> 0 | M8: =C110 -> 0 | N8: =H5 -> 0
B9: 📈 | C9: Saldo do Mês | D9: =D5-D8 -> -1184.9 | E9: =IF(D5=0,0,D9/D5) -> 0 | F9: 🤝 | G9: DOA (5%) | H9: =D5*'Configuração'!D34 -> 0 | J9: =H6 -> 0 | M9: =C111 -> 0 | N9: =H6 -> 0
B10: 🏦 | C10: SALDO FINAL | D10: =D4+D9 -> -9463.78 | E10: =D10 -> -9463.78 | J10: =H7 -> 0 | M10: =C112 -> 0 | N10: =H7 -> 0
J11: =H8 -> 0 | M11: =C113 -> 0 | N11: =H8 -> 0
B12: 💰 RECEITAS DO MÊS — DE ONDE VEM SEU DINHEIRO | J12: =H9 -> 0 | M12: =C114 -> 0 | N12: =H9 -> 0
B13: # | C13: Data | D13: Descrição da Receita | E13: Valor (R$) | F13: Fonte de Receita | G13: Recebido? | H13: Observação | M13: =C115 -> 0
B14: 1 | M14: =C116 -> 0
B15: 2 | M15: =C117 -> 0
B16: 3 | M16: =C118 -> 0
B17: 4
B18: 5
B19: 6
B20: 7
B21: 8
B22: 9 | M22: =G109 -> 200
B23: 10 | M23: =G110 -> 0
B24: 11 | M24: =G111 -> 200
B25: 12 | M25: =G112 -> 0
B26: 13 | M26: =G113 -> 470
B27: 14 | M27: =G114 -> 59.9
B28: 15 | M28: =G115 -> 0
B29: 💰 | C29: TOTAL RECEITAS DO MÊS | E29: =SUM(E14:E28) -> 0 | M29: =G116 -> 160
M30: =G117 -> 0
B31: 🔒 DESPESAS FIXAS — AUTOMÁTICAS DA CONFIGURAÇÃO (edite valores se precisar) | M31: =G118 -> 0
B32: # | C32: Venc. | D32: Descrição | E32: Valor (R$) | F32: Categoria | G32: Pago? ✅/❌ | H32: Observação | M32: =G119 -> 0
B33: 1 | C33: ='Configuração'!F39 -> 5 | D33: ='Configuração'!C39 -> Aluguel / Financiamento | E33: ='Configuração'!D39 | F33: ='Configuração'!E39 -> Moradia | M33: =G120 -> 0
B34: 2 | C34: ='Configuração'!F40 -> 10 | D34: ='Configuração'!C40 -> Condomínio | E34: ='Configuração'!D40 | F34: ='Configuração'!E40 -> Moradia | M34: =G121 -> 0
B35: 3 | C35: ='Configuração'!F41 -> 15 | D35: ='Configuração'!C41 -> IPTU (parcela) | E35: ='Configuração'!D41 | F35: ='Configuração'!E41 -> Impostos | M35: =G122 -> 0
B36: 4 | C36: ='Configuração'!F42 -> 10 | D36: ='Configuração'!C42 -> Energia Elétrica | E36: ='Configuração'!D42 -> 200 | F36: ='Configuração'!E42 -> Moradia
B37: 5 | C37: ='Configuração'!F43 -> 15 | D37: ='Configuração'!C43 -> Água / Saneamento | E37: ='Configuração'!D43 | F37: ='Configuração'!E43 -> Moradia
B38: 6 | C38: ='Configuração'!F44 -> 20 | D38: ='Configuração'!C44 -> Gás | E38: ='Configuração'!D44 | F38: ='Configuração'!E44 -> Moradia
B39: 7 | C39: ='Configuração'!F45 -> 10 | D39: ='Configuração'!C45 -> Internet | E39: ='Configuração'!D45 -> 100 | F39: ='Configuração'!E45 -> Tecnologia
B40: 8 | C40: ='Configuração'!F46 -> 12 | D40: ='Configuração'!C46 -> Celular | E40: ='Configuração'!D46 -> 60 | F40: ='Configuração'!E46 -> Tecnologia
B41: 9 | C41: ='Configuração'!F47 -> 5 | D41: ='Configuração'!C47 -> Plano de Saúde | E41: ='Configuração'!D47 | F41: ='Configuração'!E47 -> Saúde
...

Sheet Raio-X Anual
B1: 🔬 RAIO-X FINANCEIRO ANUAL — ANÁLISE TOTAL
B4: 💵 RECEITAS POR FONTE — EVOLUÇÃO MENSAL
B5: Fonte | C5: Jan | D5: Fev | E5: Mar | F5: Abr | G5: Mai | H5: Jun | I5: Jul | J5: Ago | K5: Set | L5: Out | M5: Nov | N5: Dez | O5: TOTAL
B6: Salário CLT | C6: =Janeiro!M7 -> 0 | D6: =Fevereiro!M7 -> 0 | E6: ='Março'!M7 -> 0 | F6: =Abril!M7 -> 0 | G6: =Maio!M7 -> 0 | H6: =Junho!M7 -> 0 | I6: =Julho!M7 -> 0 | J6: =Agosto!M7 -> 0 | K6: =Setembro!M7 -> 0 | L6: =Outubro!M7 -> 0 | M6: =Novembro!M7 -> 0 | N6: =Dezembro!M7 -> 0 | O6: =SUM(C6:N6) -> 0
B7: Freelance / Projetos | C7: =Janeiro!M8 -> 0 | D7: =Fevereiro!M8 -> 0 | E7: ='Março'!M8 -> 0 | F7: =Abril!M8 -> 0 | G7: =Maio!M8 -> 0 | H7: =Junho!M8 -> 0 | I7: =Julho!M8 -> 0 | J7: =Agosto!M8 -> 0 | K7: =Setembro!M8 -> 0 | L7: =Outubro!M8 -> 0 | M7: =Novembro!M8 -> 0 | N7: =Dezembro!M8 -> 0 | O7: =SUM(C7:N7) -> 0
B8: Vendas Online | C8: =Janeiro!M9 -> 0 | D8: =Fevereiro!M9 -> 0 | E8: ='Março'!M9 -> 0 | F8: =Abril!M9 -> 0 | G8: =Maio!M9 -> 0 | H8: =Junho!M9 -> 0 | I8: =Julho!M9 -> 0 | J8: =Agosto!M9 -> 0 | K8: =Setembro!M9 -> 0 | L8: =Outubro!M9 -> 0 | M8: =Novembro!M9 -> 0 | N8: =Dezembro!M9 -> 0 | O8: =SUM(C8:N8) -> 0
B9: Consultoria | C9: =Janeiro!M10 -> 0 | D9: =Fevereiro!M10 -> 0 | E9: ='Março'!M10 -> 0 | F9: =Abril!M10 -> 0 | G9: =Maio!M10 -> 0 | H9: =Junho!M10 -> 0 | I9: =Julho!M10 -> 0 | J9: =Agosto!M10 -> 0 | K9: =Setembro!M10 -> 0 | L9: =Outubro!M10 -> 0 | M9: =Novembro!M10 -> 0 | N9: =Dezembro!M10 -> 0 | O9: =SUM(C9:N9) -> 0
B10: Rendimentos / Investimentos | C10: =Janeiro!M11 -> 0 | D10: =Fevereiro!M11 -> 0 | E10: ='Março'!M11 -> 0 | F10: =Abril!M11 -> 0 | G10: =Maio!M11 -> 0 | H10: =Junho!M11 -> 0 | I10: =Julho!M11 -> 0 | J10: =Agosto!M11 -> 0 | K10: =Setembro!M11 -> 0 | L10: =Outubro!M11 -> 0 | M10: =Novembro!M11 -> 0 | N10: =Dezembro!M11 -> 0 | O10: =SUM(C10:N10) -> 0
B11: Aluguel Recebido | C11: =Janeiro!M12 -> 0 | D11: =Fevereiro!M12 -> 0 | E11: ='Março'!M12 -> 0 | F11: =Abril!M12 -> 0 | G11: =Maio!M12 -> 0 | H11: =Junho!M12 -> 0 | I11: =Julho!M12 -> 0 | J11: =Agosto!M12 -> 0 | K11: =Setembro!M12 -> 0 | L11: =Outubro!M12 -> 0 | M11: =Novembro!M12 -> 0 | N11: =Dezembro!M12 -> 0 | O11: =SUM(C11:N11) -> 0
B12: Comissões | C12: =Janeiro!M13 -> 0 | D12: =Fevereiro!M13 -> 0 | E12: ='Março'!M13 -> 0 | F12: =Abril!M13 -> 0 | G12: =Maio!M13 -> 0 | H12: =Junho!M13 -> 0 | I12: =Julho!M13 -> 0 | J12: =Agosto!M13 -> 0 | K12: =Setembro!M13 -> 0 | L12: =Outubro!M13 -> 0 | M12: =Novembro!M13 -> 0 | N12: =Dezembro!M13 -> 0 | O12: =SUM(C12:N12) -> 0
B13: Bônus / Participação | C13: =Janeiro!M14 -> 0 | D13: =Fevereiro!M14 -> 0 | E13: ='Março'!M14 -> 0 | F13: =Abril!M14 -> 0 | G13: =Maio!M14 -> 0 | H13: =Junho!M14 -> 0 | I13: =Julho!M14 -> 0 | J13: =Agosto!M14 -> 0 | K13: =Setembro!M14 -> 0 | L13: =Outubro!M14 -> 0 | M13: =Novembro!M14 -> 0 | N13: =Dezembro!M14 -> 0 | O13: =SUM(C13:N13) -> 0
B14: Renda Extra / Bico | C14: =Janeiro!M15 -> 0 | D14: =Fevereiro!M15 -> 0 | E14: ='Março'!M15 -> 0 | F14: =Abril!M15 -> 0 | G14: =Maio!M15 -> 0 | H14: =Junho!M15 -> 0 | I14: =Julho!M15 -> 0 | J14: =Agosto!M15 -> 0 | K14: =Setembro!M15 -> 0 | L14: =Outubro!M15 -> 0 | M14: =Novembro!M15 -> 0 | N14: =Dezembro!M15 -> 0 | O14: =SUM(C14:N14) -> 0
B15: Outros | C15: =Janeiro!M16 -> 0 | D15: =Fevereiro!M16 -> 0 | E15: ='Março'!M16 -> 0 | F15: =Abril!M16 -> 0 | G15: =Maio!M16 -> 0 | H15: =Junho!M16 -> 0 | I15: =Julho!M16 -> 0 | J15: =Agosto!M16 -> 0 | K15: =Setembro!M16 -> 0 | L15: =Outubro!M16 -> 0 | M15: =Novembro!M16 -> 0 | N15: =Dezembro!M16 -> 0 | O15: =SUM(C15:N15) -> 0
B16: TOTAL | C16: =SUM(C6:C15) -> 0 | D16: =SUM(D6:D15) -> 0 | E16: =SUM(E6:E15) -> 0 | F16: =SUM(F6:F15) -> 0 | G16: =SUM(G6:G15) -> 0 | H16: =SUM(H6:H15) -> 0 | I16: =SUM(I6:I15) -> 0 | J16: =SUM(J6:J15) -> 0 | ... O16: =SUM(O6:O15) -> 0
B35: 💸 DESPESAS POR CATEGORIA — EVOLUÇÃO MENSAL
B36: Categoria | C36: Jan | D36: Fev | E36: Mar | F36: Abr | G36: Mai | H36: Jun | I36: Jul | J36: Ago | K36: Set | L36: Out | M36: Nov | N36: Dez | O36: TOTAL
